2024-12-01 00:46:14,910 - INFO - [__main__] - === Starting Deployment Process ===
File "/home/runner/MediTrackPlus/deploy.py", line 276, in main

2024-12-01 00:46:14,910 - INFO - [__main__] - Deployment ID: 20241201_004614
File "/home/runner/MediTrackPlus/deploy.py", line 277, in main

2024-12-01 00:46:14,910 - INFO - [__main__] - Performing initial dependency check...
File "/home/runner/MediTrackPlus/deploy.py", line 280, in main

2024-12-01 00:46:14,910 - INFO - [__main__] - === Checking Service Dependencies ===
File "/home/runner/MediTrackPlus/deploy.py", line 34, in check_service_dependencies

2024-12-01 00:46:15,262 - INFO - [__main__] - Database connection: OK
File "/home/runner/MediTrackPlus/deploy.py", line 48, in check_service_dependencies

2024-12-01 00:46:15,263 - INFO - [__main__] - File system access: OK
File "/home/runner/MediTrackPlus/deploy.py", line 59, in check_service_dependencies

2024-12-01 00:46:15,263 - INFO - [__main__] - Port 3000 is available
File "/home/runner/MediTrackPlus/deploy.py", line 182, in check_port_availability

2024-12-01 00:46:15,263 - INFO - [__main__] - Environment variables: OK
File "/home/runner/MediTrackPlus/deploy.py", line 71, in check_service_dependencies

2024-12-01 00:46:15,263 - INFO - [__main__] - === Dependencies Status Summary ===
File "/home/runner/MediTrackPlus/deploy.py", line 76, in check_service_dependencies

2024-12-01 00:46:15,263 - INFO - [__main__] - Database: ✓
File "/home/runner/MediTrackPlus/deploy.py", line 78, in check_service_dependencies

2024-12-01 00:46:15,264 - INFO - [__main__] - File System: ✓
File "/home/runner/MediTrackPlus/deploy.py", line 78, in check_service_dependencies

2024-12-01 00:46:15,264 - INFO - [__main__] - Port Availability: ✓
File "/home/runner/MediTrackPlus/deploy.py", line 78, in check_service_dependencies

2024-12-01 00:46:15,264 - INFO - [__main__] - Environment: ✓
File "/home/runner/MediTrackPlus/deploy.py", line 78, in check_service_dependencies

2024-12-01 00:46:15,264 - INFO - [__main__] - === Executing: Checking environment variables ===
File "/home/runner/MediTrackPlus/deploy.py", line 304, in main

2024-12-01 00:46:15,264 - INFO - [__main__] - Started at: 00:46:15
File "/home/runner/MediTrackPlus/deploy.py", line 305, in main

2024-12-01 00:46:15,264 - INFO - [__main__] - All required environment variables are set
File "/home/runner/MediTrackPlus/deploy.py", line 98, in check_environment_variables

2024-12-01 00:46:15,264 - INFO - [__main__] - Completed at: 00:46:15
File "/home/runner/MediTrackPlus/deploy.py", line 313, in main

2024-12-01 00:46:15,264 - INFO - [__main__] - === Executing: Verifying database connection ===
File "/home/runner/MediTrackPlus/deploy.py", line 304, in main

2024-12-01 00:46:15,264 - INFO - [__main__] - Started at: 00:46:15
File "/home/runner/MediTrackPlus/deploy.py", line 305, in main

2024-12-01 00:46:15,265 - INFO - [__main__] - Verifying database connection...
File "/home/runner/MediTrackPlus/deploy.py", line 104, in verify_database_connection

2024-12-01 00:46:15,609 - INFO - [__main__] - Database connection successful
File "/home/runner/MediTrackPlus/deploy.py", line 107, in verify_database_connection

2024-12-01 00:46:15,610 - INFO - [__main__] - Completed at: 00:46:15
File "/home/runner/MediTrackPlus/deploy.py", line 313, in main

2024-12-01 00:46:15,616 - INFO - [__main__] - === Executing: Setting up database ===
File "/home/runner/MediTrackPlus/deploy.py", line 304, in main

2024-12-01 00:46:15,617 - INFO - [__main__] - Started at: 00:46:15
File "/home/runner/MediTrackPlus/deploy.py", line 305, in main

2024-12-01 00:46:15,617 - INFO - [__main__] - Setting up database...
File "/home/runner/MediTrackPlus/deploy.py", line 116, in setup_database

2024-12-01 00:46:17,335 - INFO - [__main__] - Database setup completed successfully
File "/home/runner/MediTrackPlus/deploy.py", line 130, in setup_database

2024-12-01 00:46:17,336 - INFO - [__main__] - Completed at: 00:46:17
File "/home/runner/MediTrackPlus/deploy.py", line 313, in main

2024-12-01 00:46:17,336 - INFO - [__main__] - === Executing: Creating upload directories ===
File "/home/runner/MediTrackPlus/deploy.py", line 304, in main

2024-12-01 00:46:17,336 - INFO - [__main__] - Started at: 00:46:17
File "/home/runner/MediTrackPlus/deploy.py", line 305, in main

2024-12-01 00:46:17,336 - INFO - [__main__] - Creating upload directories...
File "/home/runner/MediTrackPlus/deploy.py", line 145, in create_upload_directories

2024-12-01 00:46:17,337 - INFO - [__main__] - Created directory: static/uploads
File "/home/runner/MediTrackPlus/deploy.py", line 152, in create_upload_directories

2024-12-01 00:46:17,337 - INFO - [__main__] - Created directory: static/uploads/prescriptions
File "/home/runner/MediTrackPlus/deploy.py", line 152, in create_upload_directories

2024-12-01 00:46:17,337 - INFO - [__main__] - Completed at: 00:46:17
File "/home/runner/MediTrackPlus/deploy.py", line 313, in main

2024-12-01 00:46:17,337 - INFO - [__main__] - === Executing: Updating run configuration ===
File "/home/runner/MediTrackPlus/deploy.py", line 304, in main

2024-12-01 00:46:17,337 - INFO - [__main__] - Started at: 00:46:17
File "/home/runner/MediTrackPlus/deploy.py", line 305, in main

2024-12-01 00:46:17,338 - INFO - [__main__] - Updating run configuration...
File "/home/runner/MediTrackPlus/deploy.py", line 161, in update_run_configuration

2024-12-01 00:46:17,338 - INFO - [__main__] - Run configuration updated successfully
File "/home/runner/MediTrackPlus/deploy.py", line 170, in update_run_configuration

2024-12-01 00:46:17,338 - INFO - [__main__] - Completed at: 00:46:17
File "/home/runner/MediTrackPlus/deploy.py", line 313, in main

2024-12-01 00:46:17,338 - INFO - [__main__] - === Executing: Verifying application status ===
File "/home/runner/MediTrackPlus/deploy.py", line 304, in main

2024-12-01 00:46:17,339 - INFO - [__main__] - Started at: 00:46:17
File "/home/runner/MediTrackPlus/deploy.py", line 305, in main

2024-12-01 00:46:17,339 - INFO - [__main__] - === Starting Application Verification ===
File "/home/runner/MediTrackPlus/deploy.py", line 191, in verify_application_running

2024-12-01 00:46:17,339 - INFO - [__main__] - Stage 1: Initial connection check
File "/home/runner/MediTrackPlus/deploy.py", line 192, in verify_application_running

2024-12-01 00:46:17,339 - INFO - [__main__] - Attempt 1/5 - Checking main endpoint
File "/home/runner/MediTrackPlus/deploy.py", line 207, in verify_application_running

2024-12-01 00:46:17,342 - ERROR - [__main__] - Attempt 1: Connection error: HTTPConnectionPool(host='localhost', port=3000): Max retries exceeded with url: / (Caused by NewConnectionError('<urllib3.connection.HTTPConnection object at 0x7efd703c5c50>: Failed to establish a new connection: [Errno 111] Connection refused'))
File "/home/runner/MediTrackPlus/deploy.py", line 233, in verify_application_running

2024-12-01 00:46:17,343 - INFO - [__main__] - Retrying in 2 seconds...
File "/home/runner/MediTrackPlus/deploy.py", line 241, in verify_application_running

2024-12-01 00:46:19,343 - INFO - [__main__] - Attempt 2/5 - Checking main endpoint
File "/home/runner/MediTrackPlus/deploy.py", line 207, in verify_application_running

2024-12-01 00:46:19,347 - ERROR - [__main__] - Attempt 2: Connection error: HTTPConnectionPool(host='localhost', port=3000): Max retries exceeded with url: / (Caused by NewConnectionError('<urllib3.connection.HTTPConnection object at 0x7efd6ff2ee10>: Failed to establish a new connection: [Errno 111] Connection refused'))
File "/home/runner/MediTrackPlus/deploy.py", line 233, in verify_application_running

2024-12-01 00:46:19,347 - INFO - [__main__] - Retrying in 4 seconds...
File "/home/runner/MediTrackPlus/deploy.py", line 241, in verify_application_running

