2024-12-01 00:46:20,626 - INFO - [__main__] - === Starting Deployment Process ===
File "/home/runner/MediTrackPlus/deploy.py", line 276, in main

2024-12-01 00:46:20,627 - INFO - [__main__] - Deployment ID: 20241201_004620
File "/home/runner/MediTrackPlus/deploy.py", line 277, in main

2024-12-01 00:46:20,627 - INFO - [__main__] - Performing initial dependency check...
File "/home/runner/MediTrackPlus/deploy.py", line 280, in main

2024-12-01 00:46:20,627 - INFO - [__main__] - === Checking Service Dependencies ===
File "/home/runner/MediTrackPlus/deploy.py", line 34, in check_service_dependencies

2024-12-01 00:46:20,973 - INFO - [__main__] - Database connection: OK
File "/home/runner/MediTrackPlus/deploy.py", line 48, in check_service_dependencies

2024-12-01 00:46:20,974 - INFO - [__main__] - File system access: OK
File "/home/runner/MediTrackPlus/deploy.py", line 59, in check_service_dependencies

2024-12-01 00:46:20,974 - INFO - [__main__] - Port 3000 is available
File "/home/runner/MediTrackPlus/deploy.py", line 182, in check_port_availability

2024-12-01 00:46:20,974 - INFO - [__main__] - Environment variables: OK
File "/home/runner/MediTrackPlus/deploy.py", line 71, in check_service_dependencies

2024-12-01 00:46:20,975 - INFO - [__main__] - === Dependencies Status Summary ===
File "/home/runner/MediTrackPlus/deploy.py", line 76, in check_service_dependencies

2024-12-01 00:46:20,975 - INFO - [__main__] - Database: ✓
File "/home/runner/MediTrackPlus/deploy.py", line 78, in check_service_dependencies

2024-12-01 00:46:20,975 - INFO - [__main__] - File System: ✓
File "/home/runner/MediTrackPlus/deploy.py", line 78, in check_service_dependencies

2024-12-01 00:46:20,975 - INFO - [__main__] - Port Availability: ✓
File "/home/runner/MediTrackPlus/deploy.py", line 78, in check_service_dependencies

2024-12-01 00:46:20,975 - INFO - [__main__] - Environment: ✓
File "/home/runner/MediTrackPlus/deploy.py", line 78, in check_service_dependencies

2024-12-01 00:46:20,975 - INFO - [__main__] - === Executing: Checking environment variables ===
File "/home/runner/MediTrackPlus/deploy.py", line 304, in main

2024-12-01 00:46:20,975 - INFO - [__main__] - Started at: 00:46:20
File "/home/runner/MediTrackPlus/deploy.py", line 305, in main

2024-12-01 00:46:20,975 - INFO - [__main__] - All required environment variables are set
File "/home/runner/MediTrackPlus/deploy.py", line 98, in check_environment_variables

2024-12-01 00:46:20,975 - INFO - [__main__] - Completed at: 00:46:20
File "/home/runner/MediTrackPlus/deploy.py", line 313, in main

2024-12-01 00:46:20,975 - INFO - [__main__] - === Executing: Verifying database connection ===
File "/home/runner/MediTrackPlus/deploy.py", line 304, in main

2024-12-01 00:46:20,976 - INFO - [__main__] - Started at: 00:46:20
File "/home/runner/MediTrackPlus/deploy.py", line 305, in main

2024-12-01 00:46:20,976 - INFO - [__main__] - Verifying database connection...
File "/home/runner/MediTrackPlus/deploy.py", line 104, in verify_database_connection

2024-12-01 00:46:21,319 - INFO - [__main__] - Database connection successful
File "/home/runner/MediTrackPlus/deploy.py", line 107, in verify_database_connection

2024-12-01 00:46:21,320 - INFO - [__main__] - Completed at: 00:46:21
File "/home/runner/MediTrackPlus/deploy.py", line 313, in main

2024-12-01 00:46:21,320 - INFO - [__main__] - === Executing: Setting up database ===
File "/home/runner/MediTrackPlus/deploy.py", line 304, in main

2024-12-01 00:46:21,320 - INFO - [__main__] - Started at: 00:46:21
File "/home/runner/MediTrackPlus/deploy.py", line 305, in main

2024-12-01 00:46:21,320 - INFO - [__main__] - Setting up database...
File "/home/runner/MediTrackPlus/deploy.py", line 116, in setup_database

2024-12-01 00:46:23,047 - INFO - [__main__] - Database setup completed successfully
File "/home/runner/MediTrackPlus/deploy.py", line 130, in setup_database

2024-12-01 00:46:23,048 - INFO - [__main__] - Completed at: 00:46:23
File "/home/runner/MediTrackPlus/deploy.py", line 313, in main

2024-12-01 00:46:23,048 - INFO - [__main__] - === Executing: Creating upload directories ===
File "/home/runner/MediTrackPlus/deploy.py", line 304, in main

2024-12-01 00:46:23,048 - INFO - [__main__] - Started at: 00:46:23
File "/home/runner/MediTrackPlus/deploy.py", line 305, in main

2024-12-01 00:46:23,048 - INFO - [__main__] - Creating upload directories...
File "/home/runner/MediTrackPlus/deploy.py", line 145, in create_upload_directories

2024-12-01 00:46:23,048 - INFO - [__main__] - Created directory: static/uploads
File "/home/runner/MediTrackPlus/deploy.py", line 152, in create_upload_directories

2024-12-01 00:46:23,049 - INFO - [__main__] - Created directory: static/uploads/prescriptions
File "/home/runner/MediTrackPlus/deploy.py", line 152, in create_upload_directories

2024-12-01 00:46:23,049 - INFO - [__main__] - Completed at: 00:46:23
File "/home/runner/MediTrackPlus/deploy.py", line 313, in main

2024-12-01 00:46:23,049 - INFO - [__main__] - === Executing: Updating run configuration ===
File "/home/runner/MediTrackPlus/deploy.py", line 304, in main

2024-12-01 00:46:23,049 - INFO - [__main__] - Started at: 00:46:23
File "/home/runner/MediTrackPlus/deploy.py", line 305, in main

2024-12-01 00:46:23,049 - INFO - [__main__] - Updating run configuration...
File "/home/runner/MediTrackPlus/deploy.py", line 161, in update_run_configuration

2024-12-01 00:46:23,049 - INFO - [__main__] - Run configuration updated successfully
File "/home/runner/MediTrackPlus/deploy.py", line 170, in update_run_configuration

2024-12-01 00:46:23,050 - INFO - [__main__] - Completed at: 00:46:23
File "/home/runner/MediTrackPlus/deploy.py", line 313, in main

2024-12-01 00:46:23,050 - INFO - [__main__] - === Executing: Verifying application status ===
File "/home/runner/MediTrackPlus/deploy.py", line 304, in main

2024-12-01 00:46:23,050 - INFO - [__main__] - Started at: 00:46:23
File "/home/runner/MediTrackPlus/deploy.py", line 305, in main

2024-12-01 00:46:23,050 - INFO - [__main__] - === Starting Application Verification ===
File "/home/runner/MediTrackPlus/deploy.py", line 191, in verify_application_running

2024-12-01 00:46:23,050 - INFO - [__main__] - Stage 1: Initial connection check
File "/home/runner/MediTrackPlus/deploy.py", line 192, in verify_application_running

2024-12-01 00:46:23,050 - INFO - [__main__] - Attempt 1/5 - Checking main endpoint
File "/home/runner/MediTrackPlus/deploy.py", line 207, in verify_application_running

2024-12-01 00:46:23,053 - ERROR - [__main__] - Attempt 1: Connection error: HTTPConnectionPool(host='localhost', port=3000): Max retries exceeded with url: / (Caused by NewConnectionError('<urllib3.connection.HTTPConnection object at 0x7fad43925b50>: Failed to establish a new connection: [Errno 111] Connection refused'))
File "/home/runner/MediTrackPlus/deploy.py", line 233, in verify_application_running

2024-12-01 00:46:23,053 - INFO - [__main__] - Retrying in 2 seconds...
File "/home/runner/MediTrackPlus/deploy.py", line 241, in verify_application_running

2024-12-01 00:46:25,054 - INFO - [__main__] - Attempt 2/5 - Checking main endpoint
File "/home/runner/MediTrackPlus/deploy.py", line 207, in verify_application_running

2024-12-01 00:46:25,056 - ERROR - [__main__] - Attempt 2: Connection error: HTTPConnectionPool(host='localhost', port=3000): Max retries exceeded with url: / (Caused by NewConnectionError('<urllib3.connection.HTTPConnection object at 0x7fad4351ea50>: Failed to establish a new connection: [Errno 111] Connection refused'))
File "/home/runner/MediTrackPlus/deploy.py", line 233, in verify_application_running

2024-12-01 00:46:25,056 - INFO - [__main__] - Retrying in 4 seconds...
File "/home/runner/MediTrackPlus/deploy.py", line 241, in verify_application_running

2024-12-01 00:46:29,056 - INFO - [__main__] - Attempt 3/5 - Checking main endpoint
File "/home/runner/MediTrackPlus/deploy.py", line 207, in verify_application_running

2024-12-01 00:46:29,058 - ERROR - [__main__] - Attempt 3: Connection error: HTTPConnectionPool(host='localhost', port=3000): Max retries exceeded with url: / (Caused by NewConnectionError('<urllib3.connection.HTTPConnection object at 0x7fad43534bd0>: Failed to establish a new connection: [Errno 111] Connection refused'))
File "/home/runner/MediTrackPlus/deploy.py", line 233, in verify_application_running

2024-12-01 00:46:29,059 - INFO - [__main__] - Retrying in 6 seconds...
File "/home/runner/MediTrackPlus/deploy.py", line 241, in verify_application_running

2024-12-01 00:46:35,059 - INFO - [__main__] - Attempt 4/5 - Checking main endpoint
File "/home/runner/MediTrackPlus/deploy.py", line 207, in verify_application_running

2024-12-01 00:46:35,061 - ERROR - [__main__] - Attempt 4: Connection error: HTTPConnectionPool(host='localhost', port=3000): Max retries exceeded with url: / (Caused by NewConnectionError('<urllib3.connection.HTTPConnection object at 0x7fad43536b90>: Failed to establish a new connection: [Errno 111] Connection refused'))
File "/home/runner/MediTrackPlus/deploy.py", line 233, in verify_application_running

2024-12-01 00:46:35,061 - INFO - [__main__] - Retrying in 8 seconds...
File "/home/runner/MediTrackPlus/deploy.py", line 241, in verify_application_running

2024-12-01 00:46:43,062 - INFO - [__main__] - Attempt 5/5 - Checking main endpoint
File "/home/runner/MediTrackPlus/deploy.py", line 207, in verify_application_running

2024-12-01 00:46:43,065 - ERROR - [__main__] - Attempt 5: Connection error: HTTPConnectionPool(host='localhost', port=3000): Max retries exceeded with url: / (Caused by NewConnectionError('<urllib3.connection.HTTPConnection object at 0x7fad43536390>: Failed to establish a new connection: [Errno 111] Connection refused'))
File "/home/runner/MediTrackPlus/deploy.py", line 233, in verify_application_running

2024-12-01 00:46:43,065 - ERROR - [__main__] - Max retry attempts reached
File "/home/runner/MediTrackPlus/deploy.py", line 244, in verify_application_running

2024-12-01 00:46:43,066 - INFO - [__main__] - Attempting recovery procedures...
File "/home/runner/MediTrackPlus/deploy.py", line 247, in verify_application_running

2024-12-01 00:46:43,066 - INFO - [__main__] - Port 3000 is available
File "/home/runner/MediTrackPlus/deploy.py", line 182, in check_port_availability

2024-12-01 00:46:43,066 - ERROR - [__main__] - === Application Verification Failed ===
File "/home/runner/MediTrackPlus/deploy.py", line 266, in verify_application_running

2024-12-01 00:46:43,066 - ERROR - [__main__] - Step failed: Verifying application status
File "/home/runner/MediTrackPlus/deploy.py", line 308, in main

2024-12-01 00:46:43,066 - ERROR - [__main__] - === Deployment Failed ===
File "/home/runner/MediTrackPlus/deploy.py", line 331, in main

2024-12-01 00:46:43,066 - ERROR - [__main__] - Failed Steps:
File "/home/runner/MediTrackPlus/deploy.py", line 332, in main

2024-12-01 00:46:43,066 - ERROR - [__main__] - ✗ Verifying application status
File "/home/runner/MediTrackPlus/deploy.py", line 334, in main

2024-12-01 00:46:43,066 - ERROR - [__main__] - 
Please check the detailed logs in debug_20241201_004643.log
File "/home/runner/MediTrackPlus/deploy.py", line 335, in main

